Workbook
Name Data: #REF!
Name Data: #REF!
Name Data: #REF!
Name ユニット: #REF!
Name ユニット: 申込書!#REF!
Name ユニット: #REF!
Name 愛知県: #REF!
Name 愛知県: 申込書!#REF!
Name 愛知県: 入力F_設定!$S$3
Name 岐阜県: 申込書!#REF!
Name 岐阜県: 入力F_設定!$O$3:$O$6
Name 岐阜市: 入力F_設定!$O$3:$O$6
Name 京都府: 入力F_設定!$I$3:$I$38
Name 三重県: 申込書!#REF!
Name 三重県: 入力F_設定!$P$3:$P$14
Name 滋賀県: 入力F_設定!$H$3:$H$21
Name 集約需要家ID: #REF!
Name 集約需要家ID: #REF!
Name 集約需要家ID: #REF!
Name 新潟県: #REF!
Name 新潟県: #REF!
Name 新潟県: #REF!
Name 静岡県: #REF!
Name 静岡県: 申込書!#REF!
Name 静岡県: #REF!
Name 石川県: 入力F_設定!$T$3
Name 大阪府: 入力F_設定!$J$3:$J$74
Name 長野県: 申込書!#REF!
Name 長野県: 入力F_設定!$R$3
Name 都道府県: #REF!
Name 都道府県: 申込書!#REF!
Name 都道府県: #REF!
Name 奈良県: 入力F_設定!$L$3:$L$41
Name 富山県: 入力F_設定!$Q$3
Name 福井県: 入力F_設定!$N$3:$N$10
Name 兵庫県: 入力F_設定!$K$3:$K$51
Name 和歌山県: 入力F_設定!$M$3:$M$32

Sheet 入力フォーム
B1: *黄色ハッチング箇所が必須入力項目になります。 | AL1: 【入力例】
B2: 申込月日* | AJ2: 申込月日 | AT2: ****/**/** | BT2: =IF(AND(BT5,BT6,BT7,BT8,BT9,BT14,BU14,BV14,BT16,BT18,BT19,BT24,BT28),1,0) -> 0
B4: 【申込者概要】 | AJ4: 【申込者概要】
B5: 会社名* | AJ5: 会社名 | AT5: 〇〇〇〇株式会社 | BT5: =IF(L5="",0,1) -> 0
B6: 所在地* | AJ6: 所在地 | AT6: 大阪府大阪市〇〇〇 〇-〇 | BT6: =IF(L6="",0,1) -> 0
B7: 所属・担当者* | AJ7: 所属・担当者 | AT7: 〇〇 〇〇 | BT7: =IF(L7="",0,1) -> 0
B8: E-mail* | AJ8: E-mail | AT8: *****@***.co.jp | BT8: =IF(L8="",0,1) -> 0
B9: 電話番号* | AJ9: 電話番号 | AT9: 〇〇〇-〇〇〇〇 | BT9: =IF(L9="",0,1) -> 0
B10: FAX | AJ10: FAX | AT10: 〇〇〇-〇〇〇〇 | BT10: =IF(L10="",0,1) -> 0
B12: 【発電設備概要】 | AJ12: 【発電設備概要】
B13: 発電設備等の設置場所* | L13: 都道府県 | Q13: 市区町村 | X13: 番地以降 | AJ13: 発電設備等の設置場所* | AT13: 都道府県 | AY13: 市区町村 | BF13: 番地以降
AT14: 大阪府 | AY14: 大阪市北区 | BF14: 〇〇〇〇丁目ー〇 | BT14: =IF(L14="",0,1) -> 0 | BU14: =IF(Q14="",0,1) -> 0 | BV14: =IF(X14="",0,1) -> 0
B15: 発電設備等の設置場所（緯度経度）* | L15: 緯度 | R15: 経度 | X15: 緯度経度取得方法はこちら | AJ15: 発電設備等の設置場所（緯度経度）* | AT15: 緯度 | AZ15: 経度 | BF15: 緯度経度取得方法はこちら
AT16: 34.〇〇〇〇〇〇 | AZ16: 135.〇〇〇〇〇〇 | BT16: =IF(L16="",0,1) -> 0
B17: 発電設備等設置場所の位置図貼付け要否 | L17: =IF(L16="","要","否") -> 要 | P17: "要"の場合は「申込書」シートへ位置図貼付けをお願いします。 | AJ17: 発電設備等設置場所の位置図貼付け要否 | AT17: =IF(AT16="","要","否") -> 否 | AX17: "要"の場合は「申込書」シートへ位置図貼付けをお願いします。
B18: 発電設備等の種類* | AJ18: 発電設備等の種類 | AT18: 太陽光 | BT18: =IF(L18="",0,1) -> 0
B19: 発電設備等容量* | AE19: kW | AJ19: 発電設備等容量 | AT19: 10100 | BM19: kW | BT19: =IF(L19="",0,1) -> 0
B20: 自家消費電力 | AE20: kW | AJ20: 自家消費電力 | AT20: 100 | BM20: kW
B21: 最大受電電力* | L21: =IF((L19-L20)=0,"(自動計算)",(L19-L20)) -> (自動計算) | AE21: kW | AJ21: 最大受電電力 | AT21: =IF((AT19-AT20)=0,"(自動計算)",(AT19-AT20)) -> 10000 | BM21: kW
B23: 【連系先概要】 | AJ23: 【連系先概要】
B24: 連系先一般送配電事業者 又は配電事業者* | AJ24: 連系先一般送配電事業者 又は配電事業者 | AT24: 関西電力送配電株式会社 | BT24: =IF(L24="",0,1) -> 0
B26: 希望連系点 | H26: 高圧連系 | L26: 電柱番号 | AJ26: 希望連系点 | AP26: 高圧連系 | AT26: 電柱番号 | AY26: 関西 ２１号
H27: 特高連系 | L27: - | AP27: 特高連系 | AT27: -
B28: 希望受電電圧* | L28: =IF(L21="(自動計算)","(自動表示)",IF(L21<2000,"6.6",IF(L21<10000,"22(33)",IF(L21>=10000,"77"," ")))) -> (自動表示) | AE28: kV | AJ28: 希望受電電圧 | AT28: =IF(AT21="(自動計算)","(自動表示)",IF(AT21<2000,"6.6",IF(AT21<10000,"22(33)",IF(AT21>=10000,"77"," ")))) -> 77 | BM28: kV | BT28: =IF(L28="",0,1) -> 1
L29: 標準外を希望する | AE29: kV | AT29: 標準外を希望する | BA29: 275 | BM29: kV | BT29: FALSE

Sheet 申込書
A1: 事前相談申込書 | BN1: 添付書類１ | DP1: 添付書類２
G2: 様式 CK1-20240801 | N2: ◆発電設備等設置場所の緯度経度情報および位置図
F3: 申込日 | G3: =IF(入力フォーム!L2="","",入力フォーム!L2)
B5: 関西電力送配電株式会社 | E5: 御中 | O5: 発電設備等の設置場所（緯度経度） | AH5: (緯度) | AL5: =IF(入力フォーム!L16="","",入力フォーム!L16) | AU5: (経度) | AY5: =IF(入力フォーム!R16="","",入力フォーム!R16)
B7: １．申込みの概要 | P7: ※以下のスペースに貼り付けてください。
B8: 依頼者 | C8: 会社名 | E8: =IF(入力フォーム!L5="","",入力フォーム!L5)
C9: 所在地 | E9: =IF(入力フォーム!L6="","",入力フォーム!L6)
C10: 所属・担当者 | E10: =IF(入力フォーム!L7="","",入力フォーム!L7) | G10: 電話番号 | I10: =IF(入力フォーム!L9="","",入力フォーム!L9)
C11: E-mail | E11: =IF(入力フォーム!L8="","",入力フォーム!L8) | G11: FAX | I11: =IF(入力フォーム!L10="","",入力フォーム!L10)
B12: 発電設備等の 設置場所 | C12: =IF(入力フォーム!L14="","",入力フォーム!L14) | D12: =IF(入力フォーム!Q14="","",入力フォーム!Q14) | F12: =IF(入力フォーム!X14="","",入力フォーム!X14)
B13: 発電設備等の種類 | C13: =IF(入力フォーム!L18="","",入力フォーム!L18) | E13: 連系先一般送配電事業者 又は配電事業者 | G13: =IF(入力フォーム!L24="","",入力フォーム!L24)
B14: 発電設備等容量 | C14: =IF(入力フォーム!L19="","",入力フォーム!L19) | D14: kW | E14: 希望連系点※1 | F14: 高圧連系 | G14: 電柱番号 | I14: =IF(入力フォーム!Q26="","-",入力フォーム!Q26) -> -
B15: 最大受電電力※2 | C15: =IF(入力フォーム!L21="","",入力フォーム!L21) -> (自動計算) | D15: kW | F15: 特高連系 | G15: =IF(入力フォーム!L27="","-",入力フォーム!L27) -> -
E16: 希望受電電圧※3 | G16: =IF(入力フォーム!S29="",入力フォーム!L28,入力フォーム!S29) -> (自動表示) | L16: kV
B18: ※1 希望する送配電設備の連系点がありましたら、電柱番号・送電線名等をご記入ください。 ※2 電力系統側に流出する最大電力（発電設備容量－自家消費電力）をご記入ください（自家消費電力が不明の場合は記入不要です。）。 ※3 希望する連系電圧をご記入ください。
B19: ２．添付書類 （※添付書類がある場合のみご記入ください。）
B21: ・ 発電設備等設置場所の緯度経度情報および位置図
B23: ＜注意事項＞ ・ 特別高圧以上の送電系統に関しては、各一般送配電事業者がホームページ上で公表している系統 連系制約マッピング情報でも連系制限が想定される地域を確認することができます。 ・ 申込書１枚につき１箇所の連系点について確認いたします。検討料は不要です。 ・ 本申込書に対する回答内容は以下のとおりです。 【希望受電電圧が高圧であって、配電用変電所が存在する送電系統の場合】 (1)配電用変電所における配電用変圧器の熱容量に起因する連系制限の有無。連系制限がある場合 には配電用変電所における配電用変圧器の熱容量から算定される連系可能な最大受電電力 (2)最大受電電力に対してバンク逆潮流（配電用変電所における配電用変圧器の高圧側から特別高 圧側に流れる潮流をいいます。）の発生に伴う連系制限がある場合は、バンク逆潮流の対策工事 を実施せずに連系可能な最大受電電力。 (3)想定する連系点から連系を予定する配電用変電所までの既設配電線路亘長 【希望受電電圧が高圧であって、配電用変電所が存在しない一部の離島系統の場合】 (1)高圧流通設備の熱容量に起因する連系制限の有無。連系制限がある場合には高圧流通設備の熱 容量から算定される連系可能な最大受電電力 (2)想定する連系点から始点となる電気所までの既設高圧流通設備の線路亘長 【希望受電電圧が特別高圧である場合】 (1)送変電設備の熱容量に起因する連系制限の有無。連系制限がある場合には送変電設備の熱容量 から算定される連系可能な最大受電電力 (2)想定する連系点から発電設備等の設置場所までの直線距離 ・本申込書に対する回答内容は、希望する送電系統への連系可否を確定するものではありません。 ・本申込書により得た依頼者等の情報については、連系制限有無の確認および申込状況の管理、統計 に使用されます。また、電力広域的運営推進機関の送配電等業務指針に基づき、一般送配電事業者 又は配電事業者に依頼された申込内容の一部を電力広域的運営推進機関に報告する場合があります。 ※ 連系制限とは既設送変電設備の空き容量不足等により設備増強（アクセス線新設を除く）が必要な場合をいいます。
L24: 以 上
B25: 目的外使用・開示禁止

Sheet 緯度経度取得方法の例
A2: 緯度経度情報の取得について
A3: 受電希望地点の緯度経度情報をご提示いただくことで、住所情報で検討するより精度の高い回答が可能となります。
A5: ・発電設備等の設置場所（受電希望地点）の緯度経度を任意の方法で取得してください。
A6: ＜Google mapからの取得方法はこちら＞⇒ | K6: リンク
A7: ＜国土地理院地図からの取得方法はこちら＞⇒ | K7: リンク
A9: ・緯度経度は10進法で記入をお願いします。 | L9: 10進法：(緯度)〇〇.〇〇〇〇 (経度)〇〇〇.〇〇〇〇
L10: 60進法：(緯度)〇〇度〇〇分〇〇秒 (経度)〇〇〇度〇〇分〇〇秒
A11: ※60進法で取得された場合は以下黄色枠へ数値入力し、10進法へ変換のうえ記入をお願いします。
B12: ＜60進法→10進法変換表＞
B13: 入力欄 | O13: 変換結果
B14: 60進法 | O14: 10進法
B15: 緯度 | H15: 経度 | O15: 緯度 | U15: 経度
O16: =IF(B16="","",(VALUE(MID(AJ16,7,8))/60+VALUE(MID(AJ16,4,2)))/60+VALUE(LEFT(AJ16,2))) | U16: =IF(H16="","",(VALUE(MID(AK16,8,8))/60+VALUE(MID(AK16,5,2)))/60+VALUE(LEFT(AK16,3))) | AA16: ←変換結果を入力フォームへ入力してください。 | AJ16: =SUBSTITUTE(SUBSTITUTE(SUBSTITUTE(B16,"度","."),"分","."),"秒","") | AK16: =SUBSTITUTE(SUBSTITUTE(SUBSTITUTE(H16,"度","."),"分","."),"秒","")
A17: 例 | B17: 34度41分33.46秒 | H17: 135度29分32.95秒 | O17: =(VALUE(MID(AJ17,7,8))/60+VALUE(MID(AJ17,4,2)))/60+VALUE(LEFT(AJ17,2)) -> 34.692628 | U17: =(VALUE(MID(AK17,8,8))/60+VALUE(MID(AK17,5,2)))/60+VALUE(LEFT(AK17,3)) -> 135.49249 | AJ17: =SUBSTITUTE(SUBSTITUTE(SUBSTITUTE(B17,"度","."),"分","."),"秒","") -> 34.41.33.46 | AK17: =SUBSTITUTE(SUBSTITUTE(SUBSTITUTE(H17,"度","."),"分","."),"秒","") -> 135.29.32.95

Sheet 社内検討用シート
A1: 関西電力送配電社内利用シート
A2: 関西電力送配電社内の検討用として活用します。
A4: ●発電設備等設置場所特定
A5: =HYPERLINK("https://www.google.com/maps?q=" &入力フォーム!L16& ","&入力フォーム!R16," 地図上で発電設備等設置場所を表示（Googleマップ）") -> 地図上で発電設備等設置場所を表示（Googleマップ）
A8: ●入力内容転記用
B9: 申込月日* | C9: =入力フォーム!L2 -> 0
B11: 【申込者概要】
B12: 会社名* | C12: =入力フォーム!L5 -> 0
B13: 所在地* | C13: =入力フォーム!L6 -> 0
B14: 所属・担当者* | C14: =入力フォーム!L7 -> 0
B15: E-mail* | C15: =入力フォーム!L8 -> 0
B16: 電話番号* | C16: =入力フォーム!L9 -> 0
B17: FAX | C17: =入力フォーム!L10 -> 0
B19: 【発電設備概要】
B20: 発電設備等の設置場所* | C20: 都道府県 | D20: 市区町村 | E20: 番地以降
C21: =入力フォーム!L14 -> 0 | D21: =入力フォーム!Q14 -> 0 | E21: =入力フォーム!X14 -> 0
B22: 発電設備等の設置場所（緯度経度）* | C22: 緯度 | D22: 経度
C23: =入力フォーム!L16 -> 0 | D23: =入力フォーム!R16 -> 0
B24: 発電設備等設置場所の位置図貼付け要否 | C24: 要
B25: 発電設備等の種類* | C25: =入力フォーム!L18 -> 0
B26: 発電設備等容量* | C26: =入力フォーム!L19 -> 0 | D26: kW
B27: 自家消費電力 | C27: =入力フォーム!L20 -> 0 | D27: kW
B28: 最大受電電力* | C28: =入力フォーム!L21 -> (自動計算) | D28: kW
B30: 【連系先概要】
B31: 連系先一般送配電事業者 又は配電事業者* | C31: =入力フォーム!L24 -> 0
B32: 希望連系点 | C32: 高圧連系 | D32: 電柱番号 | E32: =入力フォーム!Q26 -> 0
C33: 特高連系 | D33: =入力フォーム!L27 -> -
B34: 希望受電電圧* | C34: =入力フォーム!L28 -> (自動表示) | D34: kV
C35: 標準外を希望する | D35: =入力フォーム!S29 -> 0 | E35: kV

Sheet 入力F_設定
A1: 1-1999 | B1: 2000-9999 | C1: 10000以上 | F1: 標準外
A2: 6.6 | B2: 22(33) | C2: 77 | F2: 6.6 | H2: 滋賀県 | I2: 京都府 | J2: 大阪府 | K2: 兵庫県 | L2: 奈良県 | M2: 和歌山県 | N2: 福井県 | O2: 岐阜県 | P2: 三重県 | Q2: 富山県 | R2: 長野県 | S2: 愛知県 | T2: 石川県
A3: その他 | B3: その他 | C3: 154 | F3: 22(33) | H3: 大津市 | I3: 京都市北区 | J3: 大阪市都島区 | K3: 神戸市東灘区 | L3: 奈良市 | M3: 和歌山市 | N3: 小浜市 | O3: 不破郡関ケ原町 | P3: 熊野市 | Q3: その他 | R3: その他 | S3: その他 | T3: その他
C4: 275 | F4: 77 | H4: 彦根市 | I4: 京都市上京区 | J4: 大阪市福島区 | K4: 神戸市灘区 | L4: 大和高田市 | M4: 海南市 | N4: 大飯郡おおい町 | O4: 高山市 | P4: 南牟婁郡紀宝町
C5: その他 | F5: 154 | H5: 長浜市 | I5: 京都市左京区 | J5: 大阪市此花区 | K5: 神戸市兵庫区 | L5: 大和郡山市 | M5: 橋本市 | N5: 大飯郡高浜町 | O5: 飛騨市 | P5: 南牟婁郡御浜町
A6: =IF(入力フォーム!L21<2000,"入力F_設定!A2:A3",IF(入力フォーム!L21<10000,"入力F_設定!B2:B3","入力F_設定!C2:C5")) -> 入力F_設定!C2:C5 | F6: 275 | H6: 近江八幡市 | I6: 京都市中京区 | J6: 大阪市西区 | K6: 神戸市長田区 | L6: 天理市 | M6: 有田市 | N6: 三方郡美浜町 | O6: その他 | P6: いなべ市
A7: =IF(入力フォーム!AT21<2000,"入力F_設定!A2:A3",IF(入力フォーム!AT21<10000,"入力F_設定!B2:B3","入力F_設定!C2:C5")) -> 入力F_設定!C2:C5 | F7: 500 | H7: 草津市 | I7: 京都市東山区 | J7: 大阪市港区 | K7: 神戸市須磨区 | L7: 橿原市 | M7: 御坊市 | N7: 三方上中郡若狭町 | P7: 員弁郡東員町
H8: 守山市 | I8: 京都市下京区 | J8: 大阪市大正区 | K8: 神戸市垂水区 | L8: 桜井市 | M8: 田辺市 | N8: 吉田郡永平寺町 | P8: 桑名郡木曽岬町
H9: 栗東市 | I9: 京都市南区 | J9: 大阪市天王寺区 | K9: 神戸市北区 | L9: 五條市 | M9: 新宮市 | N9: 坂井市 | P9: 桑名市
H10: 甲賀市 | I10: 京都市右京区 | J10: 大阪市浪速区 | K10: 神戸市中央区 | L10: 御所市 | M10: 紀の川市 | N10: その他 | P10: 三重郡朝日町
H11: 野洲市 | I11: 京都市伏見区 | J11: 大阪市西淀川区 | K11: 神戸市西区 | L11: 生駒市 | M11: 岩出市 | P11: 三重郡川越町
H12: 湖南市 | I12: 京都市山科区 | J12: 大阪市東淀川区 | K12: 姫路市 | L12: 香芝市 | M12: 海草郡紀美野町 | P12: 三重郡菰野町
H13: 高島市 | I13: 京都市西京区 | J13: 大阪市東成区 | K13: 尼崎市 | L13: 葛城市 | M13: 伊都郡かつらぎ町 | P13: 四日市市
H14: 東近江市 | I14: 福知山市 | J14: 大阪市生野区 | K14: 明石市 | L14: 宇陀市 | M14: 伊都郡九度山町 | P14: その他
H15: 米原市 | I15: 舞鶴市 | J15: 大阪市旭区 | K15: 西宮市 | L15: 山辺郡山添村 | M15: 伊都郡高野町
H16: 日野町 | I16: 綾部市 | J16: 大阪市城東区 | K16: 洲本市 | L16: 生駒郡平群町 | M16: 有田郡湯浅町
H17: 竜王町 | I17: 宇治市 | J17: 大阪市阿倍野区 | K17: 芦屋市 | L17: 生駒郡三郷町 | M17: 有田郡広川町
H18: 愛荘町 | I18: 宮津市 | J18: 大阪市住吉区 | K18: 伊丹市 | L18: 生駒郡斑鳩町 | M18: 有田郡有田川町
H19: 豊郷町 | I19: 亀岡市 | J19: 大阪市東住吉区 | K19: 相生市 | L19: 生駒郡安堵町 | M19: 日高郡美浜町
H20: 甲良町 | I20: 城陽市 | J20: 大阪市西成区 | K20: 豊岡市 | L20: 磯城郡川西町 | M20: 日高郡日高町
H21: 多賀町 | I21: 向日市 | J21: 大阪市淀川区 | K21: 加古川市 | L21: 磯城郡三宅町 | M21: 日高郡由良町
I22: 長岡京市 | J22: 大阪市鶴見区 | K22: 赤穂市 | L22: 磯城郡田原本町 | M22: 日高郡印南町
I23: 八幡市 | J23: 大阪市住之江区 | K23: 西脇市 | L23: 宇陀郡曽爾村 | M23: 日高郡みなべ町
I24: 京田辺市 | J24: 大阪市平野区 | K24: 宝塚市 | L24: 宇陀郡御杖村 | M24: 日高郡日高川町
I25: 京丹後市 | J25: 大阪市北区 | K25: 三木市 | L25: 高市郡高取町 | M25: 西牟婁郡白浜町
I26: 南丹市 | J26: 大阪市中央区 | K26: 高砂市 | L26: 高市郡明日香村 | M26: 西牟婁郡上富田町
I27: 木津川市 | J27: 堺市堺区 | K27: 川西市 | L27: 北葛城郡上牧町 | M27: 西牟婁郡すさみ町
I28: 乙訓郡大山崎町 | J28: 堺市中区 | K28: 小野市 | L28: 北葛城郡王寺町 | M28: 東牟婁郡那智勝浦町
I29: 久世郡久御山町 | J29: 堺市東区 | K29: 三田市 | L29: 北葛城郡広陵町 | M29: 東牟婁郡太地町
I30: 綴喜郡井手町 | J30: 堺市西区 | K30: 加西市 | L30: 北葛城郡河合町 | M30: 東牟婁郡古座川町
I31: 綴喜郡宇治田原町 | J31: 堺市南区 | K31: 丹波篠山市 | L31: 吉野郡吉野町 | M31: 東牟婁郡北山村
I32: 相楽郡笠置町 | J32: 堺市北区 | K32: 養父市 | L32: 吉野郡大淀町 | M32: 東牟婁郡串本町
I33: 相楽郡和束町 | J33: 堺市美原区 | K33: 丹波市 | L33: 吉野郡下市町
I34: 相楽郡精華町 | J34: 岸和田市 | K34: 南あわじ市 | L34: 吉野郡黒滝村
I35: 相楽郡南山城村 | J35: 豊中市 | K35: 朝来市 | L35: 吉野郡天川村
I36: 船井郡京丹波町 | J36: 池田市 | K36: 淡路市 | L36: 吉野郡野迫川村
I37: 与謝郡伊根町 | J37: 吹田市 | K37: 宍粟市 | L37: 吉野郡十津川村
I38: 与謝郡与謝野町 | J38: 泉大津市 | K38: 加東市 | L38: 吉野郡下北山村
J39: 高槻市 | K39: たつの市 | L39: 吉野郡上北山村
J40: 貝塚市 | K40: 川辺郡猪名川町 | L40: 吉野郡川上村
...
