Workbook

Sheet Summary
A1: Village thinning plan (間伐) - R6-R8 summary. Source: scan 261013_1222_001.pdf (village hall, 2026-10-08). Plans, not realised harvests.
A3: Plan year | B3: Parcels | C3: Area ha | D3: Standing vol m³ | E3: Thinning vol m³ | F3: …of which Cut & leave m³ | G3: …of which Extracted m³ | H3: Cut&leave share | I3: Thinning vol t dry (×density) | J3: Recoverable CHP fuel, t dry/yr | K3: Covers low demand (450 t) | L3: Covers high demand (600 t)
A4: R6 (FY2024) | B4: =COUNTIF(Data!$A$2:$A$114,A4) | C4: =SUMIFS(Data!$I$2:$I$114,Data!$A$2:$A$114,A4) | D4: =SUMIFS(Data!$L$2:$L$114,Data!$A$2:$A$114,A4) | E4: =SUMIFS(Data!$N$2:$N$114,Data!$A$2:$A$114,A4) | F4: =SUMIFS(Data!$N$2:$N$114,Data!$A$2:$A$114,A4,Data!$M$2:$M$114,"Cut*") | G4: =SUMIFS(Data!$N$2:$N$114,Data!$A$2:$A$114,A4,Data!$M$2:$M$114,"Extr*") | H4: =F4/E4 | I4: =E4*Assumptions!$B$2 | J4: =F4*Assumptions!$B$3*Assumptions!$B$2 | K4: =J4/Assumptions!$B$5 | L4: =J4/Assumptions!$B$6
A5: R7 (FY2025) | B5: =COUNTIF(Data!$A$2:$A$114,A5) | C5: =SUMIFS(Data!$I$2:$I$114,Data!$A$2:$A$114,A5) | D5: =SUMIFS(Data!$L$2:$L$114,Data!$A$2:$A$114,A5) | E5: =SUMIFS(Data!$N$2:$N$114,Data!$A$2:$A$114,A5) | F5: =SUMIFS(Data!$N$2:$N$114,Data!$A$2:$A$114,A5,Data!$M$2:$M$114,"Cut*") | G5: =SUMIFS(Data!$N$2:$N$114,Data!$A$2:$A$114,A5,Data!$M$2:$M$114,"Extr*") | H5: =F5/E5 | I5: =E5*Assumptions!$B$2 | J5: =F5*Assumptions!$B$3*Assumptions!$B$2 | K5: =J5/Assumptions!$B$5 | L5: =J5/Assumptions!$B$6
A6: R8 (FY2026) | B6: =COUNTIF(Data!$A$2:$A$114,A6) | C6: =SUMIFS(Data!$I$2:$I$114,Data!$A$2:$A$114,A6) | D6: =SUMIFS(Data!$L$2:$L$114,Data!$A$2:$A$114,A6) | E6: =SUMIFS(Data!$N$2:$N$114,Data!$A$2:$A$114,A6) | F6: =SUMIFS(Data!$N$2:$N$114,Data!$A$2:$A$114,A6,Data!$M$2:$M$114,"Cut*") | G6: =SUMIFS(Data!$N$2:$N$114,Data!$A$2:$A$114,A6,Data!$M$2:$M$114,"Extr*") | H6: =F6/E6 | I6: =E6*Assumptions!$B$2 | J6: =F6*Assumptions!$B$3*Assumptions!$B$2 | K6: =J6/Assumptions!$B$5 | L6: =J6/Assumptions!$B$6
A7: Total | B7: =SUM(B4:B6) | C7: =SUM(C4:C6) | D7: =SUM(D4:D6) | E7: =SUM(E4:E6) | F7: =SUM(F4:F6) | G7: =SUM(G4:G6) | H7: =F7/E7 | I7: =SUM(I4:I6) | J7: =SUM(J4:J6)
A9: Reading: "Recoverable CHP fuel" = cut-&-leave m³ × recovery share (Assumptions B3) × density. Coverage ≥1.0x means the village plan alone could feed one 50 kWe unit for 24 h/yr operation (on paper, if wood were routed to it).
A11: By Oaza 大字 (all years)
A12: Oaza | B12: Parcels | C12: Area ha | D12: Thinning vol m³ | E12: Cut & leave m³ | F12: Extracted m³ | G12: Share of village thinning
A13: 菅野 | B13: =COUNTIF(Data!$D$2:$D$114,A13) | C13: =SUMIFS(Data!$I$2:$I$114,Data!$D$2:$D$114,A13) | D13: =SUMIFS(Data!$N$2:$N$114,Data!$D$2:$D$114,A13) | E13: =SUMIFS(Data!$N$2:$N$114,Data!$D$2:$D$114,A13,Data!$M$2:$M$114,"Cut*") | F13: =SUMIFS(Data!$N$2:$N$114,Data!$D$2:$D$114,A13,Data!$M$2:$M$114,"Extr*") | G13: =D13/$E$7
A14: 神末 | B14: =COUNTIF(Data!$D$2:$D$114,A14) | C14: =SUMIFS(Data!$I$2:$I$114,Data!$D$2:$D$114,A14) | D14: =SUMIFS(Data!$N$2:$N$114,Data!$D$2:$D$114,A14) | E14: =SUMIFS(Data!$N$2:$N$114,Data!$D$2:$D$114,A14,Data!$M$2:$M$114,"Cut*") | F14: =SUMIFS(Data!$N$2:$N$114,Data!$D$2:$D$114,A14,Data!$M$2:$M$114,"Extr*") | G14: =D14/$E$7
A15: 土屋原 | B15: =COUNTIF(Data!$D$2:$D$114,A15) | C15: =SUMIFS(Data!$I$2:$I$114,Data!$D$2:$D$114,A15) | D15: =SUMIFS(Data!$N$2:$N$114,Data!$D$2:$D$114,A15) | E15: =SUMIFS(Data!$N$2:$N$114,Data!$D$2:$D$114,A15,Data!$M$2:$M$114,"Cut*") | F15: =SUMIFS(Data!$N$2:$N$114,Data!$D$2:$D$114,A15,Data!$M$2:$M$114,"Extr*") | G15: =D15/$E$7
A16: 桃俣 | B16: =COUNTIF(Data!$D$2:$D$114,A16) | C16: =SUMIFS(Data!$I$2:$I$114,Data!$D$2:$D$114,A16) | D16: =SUMIFS(Data!$N$2:$N$114,Data!$D$2:$D$114,A16) | E16: =SUMIFS(Data!$N$2:$N$114,Data!$D$2:$D$114,A16,Data!$M$2:$M$114,"Cut*") | F16: =SUMIFS(Data!$N$2:$N$114,Data!$D$2:$D$114,A16,Data!$M$2:$M$114,"Extr*") | G16: =D16/$E$7
A18: By program 事業名 (all years)
A19: Program | B19: Parcels | C19: Area ha | D19: Thinning vol m³ | E19: Subsidy rate (typ.)
A20: 施業放置林整備事業 | B20: =COUNTIF(Data!$Q$2:$Q$114,A20) | C20: =SUMIFS(Data!$I$2:$I$114,Data!$Q$2:$Q$114,A20) | D20: =SUMIFS(Data!$N$2:$N$114,Data!$Q$2:$Q$114,A20) | E20: 34%
A21: 美しい森林づくり基盤整備事業 | B21: =COUNTIF(Data!$Q$2:$Q$114,A21) | C21: =SUMIFS(Data!$I$2:$I$114,Data!$Q$2:$Q$114,A21) | D21: =SUMIFS(Data!$N$2:$N$114,Data!$Q$2:$Q$114,A21) | E21: 20% (requested)
A22: 森林資源適正推進事業 | B22: =COUNTIF(Data!$Q$2:$Q$114,A22) | C22: =SUMIFS(Data!$I$2:$I$114,Data!$Q$2:$Q$114,A22) | D22: =SUMIFS(Data!$N$2:$N$114,Data!$Q$2:$Q$114,A22) | E22: 20-30%

Sheet Data
A1: Plan year | B1: No. | C1: Owner type | D1: Oaza 大字 | E1: Chiban 地番 | F1: Rinban 林班 | G1: Shohan 小班 | H1: Operation no. 施業番号 | I1: Area ha | J1: Species | K1: Stand age | L1: Standing vol m³ | M1: Thinning method | N1: Thinning vol m³ | O1: Thinning rate % | P1: Subsidy request | Q1: Program 事業名 | R1: Thin vol ÷ standing % | S1: Check
A2: R6 (FY2024) | B2: 301 | C2: 森林所有者 | D2: 神末 | E2: 2229-3 | F2: 15 | G2: イ | H2: (1.2.4)チ | I2: 0.33 | J2: スギ/ヒノキ | K2: 55 | L2: 85 | M2: Cut & leave (伐捨) | N2: 29 | O2: 34 | Q2: 施業放置林整備事業 | R2: =N2/L2*100 | S2: ok
A3: R6 (FY2024) | B3: 302 | C3: 森林所有者 | D3: 神末 | E3: 2179-86.-87 | F3: 15 | G3: イ | H3: (1.2.3.4.5.6.7)ノチ | I3: 3.82 | J3: スギ/ヒノキ | K3: 55 | L3: 982 | M3: Cut & leave (伐捨) | N3: 334 | O3: 34 | Q3: 施業放置林整備事業 | R3: =N3/L3*100 | S3: ok
A4: R6 (FY2024) | B4: 303 | C4: 森林所有者 | D4: 神末 | E4: 1884-69 | F4: 18 | G4: 二 | H4: 4ノチ | I4: 0.9 | J4: スギ/ヒノキ | K4: 58 | L4: 288 | M4: Cut & leave (伐捨) | N4: 98 | O4: 34 | Q4: 施業放置林整備事業 | R4: =N4/L4*100 | S4: ok
A5: R6 (FY2024) | B5: 304 | C5: 森林所有者 | D5: 神末 | E5: 1756-1 | F5: 27 | G5: 八 | H5: (3.4)ウチ | I5: 1.58 | J5: スギ/ヒノキ | K5: 54 | L5: 406 | M5: Cut & leave (伐捨) | N5: 139 | O5: 34 | Q5: 施業放置林整備事業 | R5: =N5/L5*100 | S5: ok
A6: R6 (FY2024) | B6: 305 | C6: 森林所有者 | D6: 神末 | E6: 1737-1.1738-1.1739 | F6: 27 | G6: 木二 | H6: (1.2)チ(9.10)ノチ | I6: 0.93 | J6: スギ/ヒノキ | K6: 50 | L6: 239 | M6: Cut & leave (伐捨) | N6: 82 | O6: 34 | Q6: 施業放置林整備事業 | R6: =N6/L6*100 | S6: ok
A7: R6 (FY2024) | B7: 306 | C7: 森林所有者 | D7: 神末 | E7: 1604.1623.1624 | F7: 28 | G7: 八 | H7: (10~12)ノウチ | I7: 2.39 | J7: スギ/ヒノキ | K7: 59 | L7: 765 | M7: Cut & leave (伐捨) | N7: 261 | O7: 34 | Q7: 施業放置林整備事業 | R7: =N7/L7*100 | S7: ok
A8: R6 (FY2024) | B8: 307 | C8: 森林所有者 | D8: 神末 | E8: 1621.1622 | F8: 28 | G8: 八 | H8: 13ノウチ | I8: 0.13 | J8: スギ/ヒノキ | K8: 58 | L8: 42 | M8: Cut & leave (伐捨) | N8: 15 | O8: 34 | Q8: 施業放置林整備事業 | R8: =N8/L8*100 | S8: ok
A9: R6 (FY2024) | B9: 308 | C9: 森林所有者 | D9: 神末 | E9: É 1604 | F9: 28 | G9: 二 | H9: 1ノチ | I9: 0.3 | J9: スギ/ヒノキ | K9: 58 | L9: 96 | M9: Cut & leave (伐捨) | N9: 33 | O9: 34 | Q9: 施業放置林整備事業 | R9: =N9/L9*100 | S9: ok
A10: R6 (FY2024) | B10: 309 | C10: 森林所有者 | D10: 神末 | E10: 1166.1167.1169 | F10: 29 | G10: ル卜 | H10: 12)チ(6.10)ノチ | I10: 0.44 | J10: スギ/ヒノキ | K10: 55 | L10: 113 | M10: Cut & leave (伐捨) | N10: 39 | O10: 34 | Q10: 施業放置林整備事業 | R10: =N10/L10*100 | S10: ok
A11: R6 (FY2024) | B11: 310 | C11: 森林所有者 | D11: 神末 | E11: 48.-114.-136.-137.-141.-143. 020 | F11: 30 | G11: イ | H11: (18~22.24.26.37)/チ | I11: 2.41 | J11: スギ/ヒノキ | K11: 56 | L11: 771 | M11: Cut & leave (伐捨) | N11: 263 | O11: 34 | Q11: 施業放置林整備事業 | R11: =N11/L11*100 | S11: ok
A12: R6 (FY2024) | B12: 311 | C12: 森林所有者 | D12: 菅野 | E12: 2168.2960-36 | F12: 34 | G12: 八二 | H12: (25.28)/チ(3.4)ノチ | I12: 1.35 | J12: スギ/ヒノキ | K12: 31 | L12: 279 | M12: Cut & leave (伐捨) | N12: 96 | O12: 34 | Q12: 施業放置林整備事業 | R12: =N12/L12*100 | S12: ok
A13: R6 (FY2024) | B13: 312 | C13: 森林所有者 | D13: 菅野 | E13: 2960-185 | F13: 35 | G13: イ | H13: (16.17)ノチ | I13: 0.99 | J13: スギ/ヒノキ | K13: 59 | L13: 317 | M13: Cut & leave (伐捨) | N13: 108 | O13: 34 | Q13: 施業放置林整備事業 | R13: =N13/L13*100 | S13: ok
... A33: R6 (FY2024) | B33: 341 | C33: 森林所有者 | D33: 菅野 | E33: 2361.1788-219 | F33: 96 | G33: 八 口 | H33: (19.20.29)チ1/チ | I33: 0.65 | J33: スギ/ヒノキ | K33: 64 | L33: 220 | M33: Cut & leave (伐捨) | N33: 75 | O33: 34 | Q33: 施業放置林整備事業 | R33: =N33/L33*100 | S33: ok
A34: R6 (FY2024) | B34: 351 | C34: 森林所有者 | D34: 神末 | E34: 1810-1 | F34: 22 | G34: 八 F | H34: 2ノウチ4ノウチ4ノチ3ノウチ(2.3)ノウチ | I34: 9.92 | J34: スギ/ヒノキ | K34: 67 | L34: 3353 | M34: Cut & leave (伐捨) | N34: 671 | O34: 20 | P34: 希望 | Q34: 美しい森林づくり基盤整備事業 | R34: =N34/L34*100 | S34: ok
A35: R6 (FY2024) | B35: 352 | C35: 森林所有者 | D35: 桃俣 | E35: 1786-1 | F35: 72 | G35: 口 | H35: (1.5)チ | I35: 3.66 | J35: スギ/ヒノキ | K35: 60 | L35: 1171 | M35: Extracted (搬出) | N35: 235 | O35: 20 | P35: 希望 | Q35: 美しい森林づくり基盤整備事業 | R35: =N35/L35*100 | S35: ok
A36: R6 (FY2024) | B36: 359 | C36: 森林所有者 | D36: 土屋原 | E36: 3278-1/ウチ | F36: 56 | G36: 口 | H36: 1/チ | I36: 4.2 | J36: スギ/ヒノキ | K36: 80 | L36: 1420 | M36: Extracted (搬出) | N36: 284 | O36: 20 | P36: 希望 | Q36: 美しい森林づくり基盤整備事業 | R36: =N36/L36*100 | S36: ok
A37: R6 (FY2024) | B37: 372 | C37: 森林所有者 | D37: 神末 | F37: 27 | G37: ^ | H37: (7.8)チ | I37: 0.35 | J37: スギ/ヒノキ | K37: 66 | L37: 118 | M37: Cut & leave (伐捨) | N37: 36 | O37: 30 | Q37: 森林資源適正推進事業 | R37: =N37/L37*100 | S37: ok
A38: R7 (FY2025) | B38: 354 | C38: 森林所有者 | D38: 土屋原 | E38: 2860.2866.2792-35 | F38: 54 | G38: 八 | H38: 18.19.37 | I38: 3.4 | J38: スギ/ヒノキ | K38: 60 | L38: 1088 | M38: Extracted (搬出) | N38: 218 | O38: 20 | P38: 希望 | Q38: 美しい森林づくり基盤整備事業 | R38: =N38/L38*100 | S38: ok
A39: R7 (FY2025) | B39: 356 | C39: 森林所有者 | D39: 桃俣 | E39: 1772-79 | F39: 82 | G39: 千 | H39: (12.16.17.18.19)チ | I39: 0.21 | J39: スギ/ヒノキ | K39: 69 | L39: 71 | M39: Extracted (搬出) | N39: 15 | O39: 20 | Q39: 森林資源適正推進事業 | R39: =N39/L39*100 | S39: ok
A40: R7 (FY2025) | B40: 401 | C40: 森林所有者 | D40: 神末 | E40: 3059-336 | F40: 10 | G40: 口八 | H40: 1ノウチ(1~8.11)ノウチ | I40: 7.78 | J40: スギ/ヒノキ | K40: 31 | L40: 1610 | M40: Cut & leave (伐捨) | N40: 548 | O40: 34 | Q40: 施業放置林整備事業 | R40: =N40/L40*100 | S40: ok
A41: R7 (FY2025) | B41: 402 | C41: 森林所有者 | D41: 神末 | E41: 2933 | F41: 12 | G41: イ | H41: (8.9)ノウチ | I41: 0.29 | J41: スギ/ヒノキ | K41: 62 | L41: 98 | M41: Cut & leave (伐捨) | N41: 34 | O41: 34 | Q41: 施業放置林整備事業 | R41: =N41/L41*100 | S41: ok
A42: R7 (FY2025) | B42: 404 | C42: 森林所有者 | D42: 神末 | E42: 2267.2258-1.-2 2264.2265.2179-162.-163. | F42: 14 | G42: ホ | H42: (8~12)ノウチ | I42: 4.98 | J42: スギ/ヒノキ | K42: 76 | L42: 1683 | M42: Cut & leave (伐捨) | N42: 573 | O42: 34 | Q42: 施業放置林整備事業 | R42: =N42/L42*100 | S42: ok
A43: R7 (FY2025) | B43: 405 | C43: 森林所有者 | D43: 神末 | E43: 2179-104.-252 | F43: 16 | G43: 八 | H43: (6~9)ノウチ | I43: 4.95 | J43: スギ/ヒノキ | K43: 58 | L43: 1584 | M43: Cut & leave (伐捨) | N43: 539 | O43: 34 | Q43: 施業放置林整備事業 | R43: =N43/L43*100 | S43: ok
A44: R7 (FY2025) | B44: 406 | C44: 森林所有者 | D44: 菅野 | E44: 2960-118.-119 | F44: 34 | G44: 口 | H44: (9.10.14)ノウチ | I44: 0.55 | J44: スギ/ヒノキ | K44: 50 | L44: 141 | M44: Cut & leave (伐捨) | N44: 49 | O44: 34 | Q44: 施業放置林整備事業 | R44: =N44/L44*100 | S44: ok
A45: R7 (FY2025) | B45: 407 | C45: 森林所有者 | D45: 菅野 | E45: 2960-105.-106 | F45: 35 | G45: 八 | H45: (14.16~20.23)ノウチ | I45: 3.97 | J45: スギ/ヒノキ | K45: 63 | L45: 1342 | M45: Cut & leave (伐捨) | N45: 457 | O45: 34 | Q45: 施業放置林整備事業 | R45: =N45/L45*100 | S45: ok
A46: R7 (FY2025) | B46: 408 | C46: 森林所有者 | D46: 菅野 | E46: 1068-100 | F46: 38 | G46: 二 | H46: (14.16)ノウチ | I46: 0.14 | J46: スギ/ヒノキ | K46: 64 | L46: 47 | M46: Cut & leave (伐捨) | N46: 17 | O46: 34 | Q46: 施業放置林整備事業 | R46: =N46/L46*100 | S46: ok
A47: R7 (FY2025) | B47: 409 | C47: 森林所有者 | D47: 菅野 | E47: 1032-29 | F47: 44 | H47: (3.4.6)ノウチ1ノウチ | I47: 2.68 | J47: スギ/ヒノキ | K47: 59 | L47: 858 | M47: Cut & leave (伐捨) | N47: 292 | O47: 34 | Q47: 施業放置林整備事業 | R47: =N47/L47*100 | S47: ok
A48: R7 (FY2025) | B48: 410 | C48: 森林所有者 | D48: 菅野 | E48: 2960-26.-1474 | F48: 34 | H48: 13ノウチ10ノウチ(1.2)ノウチ | I48: 2 | J48: スギ/ヒノキ | K48: 56 | L48: 640 | M48: Cut & leave (伐捨) | N48: 218 | O48: 34 | Q48: 施業放置林整備事業 | R48: =N48/L48*100 | S48: ok
A49: R7 (FY2025) | B49: 411 | C49: 森林所有者 | D49: 土屋原 | E49: 2436-71 | F49: 51 | G49: 口 | H49: (35.36.37)ノウチ | I49: 1.11 | J49: スギ/ヒノキ | K49: 70 | L49: 375 | M49: Cut & leave (伐捨) | N49: 128 | O49: 34 | Q49: 施業放置林整備事業 | R49: =N49/L49*100 | S49: ok
A50: R7 (FY2025) | B50: 412 | C50: 森林所有者 | D50: 神末 | E50: 3059-334.-335 | G50: ホ二イ | H50: 1ノウチ(1.5.7)ノウチ9ノウチ | I50: 5.27 | J50: スギ/ヒノキ | K50: 87 | L50: 1781 | M50: Cut & leave (伐捨) | N50: 606 | O50: 34 | Q50: 施業放置林整備事業 | R50: =N50/L50*100 | S50: ok
A51: R7 (FY2025) | B51: 413 | C51: 森林所有者 | D51: 土屋原 | E51: 3282-116 | F51: 66 | G51: 卜 | H51: (5.6.7.8.10.14)ノウチ | I51: 0.98 | J51: スギ/ヒノキ | K51: 56 | L51: 314 | M51: Cut & leave (伐捨) | N51: 107 | O51: 34 | Q51: 施業放置林整備事業 | R51: =N51/L51*100 | S51: ok
A52: R7 (FY2025) | B52: 414 | C52: 森林所有者 | D52: 土屋原 | E52: 951.952.953 | F52: 68 | G52: ホ | H52: (5.7.8.9)ノウチ | I52: 1.22 | J52: スギ/ヒノキ | K52: 61 | L52: 412 | M52: Cut & leave (伐捨) | N52: 141 | O52: 34 | Q52: 施業放置林整備事業 | R52: =N52/L52*100 | S52: ok
A53: R7 (FY2025) | B53: 418 | C53: 森林所有者 | D53: 桃俣 | E53: 1773-92 | F53: 75 | G53: イ | H53: (20.21.22)ノウチ | I53: 0.43 | J53: スギ/ヒノキ | K53: 54 | L53: 111 | M53: Cut & leave (伐捨) | N53: 38 | O53: 34 | Q53: 施業放置林整備事業 | R53: =N53/L53*100 | S53: ok
A54: R7 (FY2025) | B54: 420 | C54: 森林所有者 | D54: 桃俣 | E54: 1773-158.-159.-160 | F54: 73 | G54: 八二 | H54: (7.8.9.14)ノウチ(2.9)ノウチ | I54: 2.12 | J54: スギ/ヒノキ | K54: 58 | L54: 678 | M54: Cut & leave (伐捨) | N54: 231 | O54: 34 | Q54: 施業放置林整備事業 | R54: =N54/L54*100 | S54: ok
A55: R7 (FY2025) | B55: 421 | C55: 森林所有者 | D55: 桃俣 | E55: 1773-137 | F55: 77 44 | G55: < | H55: (32.34.35.43)ノウチ3ノウチ | I55: 0.48 | J55: スギ/ヒノキ | K55: 60 | L55: 154 | M55: Cut & leave (伐捨) | N55: 53 | O55: 34 | Q55: 施業放置林整備事業 | R55: =N55/L55*100 | S55: ok
A56: R7 (FY2025) | B56: 422 | C56: 森林所有者 | D56: 桃俣 | E56: 1773-78.-82 | F56: 75 | G56: 口八 | H56: (11.12.16.17)/ウチ(2.8.9.14.16)/ウ | I56: 1.19 | J56: スギ/ヒノキ | K56: 61 | L56: 402 | M56: Cut & leave (伐捨) | N56: 137 | O56: 34 | Q56: 施業放置林整備事業 | R56: =N56/L56*100 | S56: ok
A57: R7 (FY2025) | B57: 423 | C57: 森林所有者 | D57: 桃俣 | E57: 1772-86 | F57: 81 | G57: イ | H57: (18.19.20~23)ノウチ | I57: 0.71 | J57: スギ/ヒノキ | K57: 55 | L57: 182 | M57: Cut & leave (伐捨) | N57: 63 | O57: 34 | Q57: 施業放置林整備事業 | R57: =N57/L57*100 | S57: ok
A58: R7 (FY2025) | B58: 424 | C58: 森林所有者 | D58: 桃俣 | E58: 1359 | F58: 22 | G58: 口 1 | H58: (8.9)/ウチ(16.17.23.24)/ウチ(11.12.13)/ウチ | I58: 2.69 | J58: スギ/ヒノキ | K58: 42 | L58: 691 | M58: Cut & leave (伐捨) | N58: 236 | O58: 34 | Q58: 施業放置林整備事業 | R58: =N58/L58*100 | S58: ok
A59: R7 (FY2025) | B59: 425 | C59: 森林所有者 | D59: 桃俣 | E59: 1340.1341 | F59: 83 | G59: 二 | H59: (2.8)/ウチ(6.7)/ウチ(18.19~22)ノウチ | I59: 1.05 | J59: スギ/ヒノキ | K59: 42 | L59: 270 | M59: Cut & leave (伐捨) | N59: 92 | O59: 34 | Q59: 施業放置林整備事業 | R59: =N59/L59*100 | S59: ok
...

Sheet Assumptions
A1: Parameter | B1: Value | C1: Source / note
A2: Dry density, sugi (t/m³) | B2: 0.314 | C2: Forest Twin density, from mitsue_50kwe_prototype_fuel_demand.md
A3: Share of thinning vol usable as CHP chip fuel | B3: 0.3 | C3: ASSUMPTION - tops, bent/small stems, low-grade; adjust after talking to the coop
A4: Share of cut-&-leave wood that can be recovered | B4: 0.3 | C4: ASSUMPTION - slope/access/cost; cut-&-leave wood is not extracted today
A5: CHP demand low (t dry/yr) | B5: 450 | C5: 50 kWe, 24 h; same doc, planning figure
A6: CHP demand high (t dry/yr) | B6: 600 | C6: same

Sheet Fuel candidates
A1: Parcels ranked by thinning volume (≥100 m³) - largest first. Check ownership/access before anything else. Cut & leave = wood is currently left in forest.
A2: Plan year | B2: No. | C2: Oaza | D2: Chiban | E2: Rinban | F2: Area ha | G2: Age | H2: Thinning m³ | I2: Method | J2: Program | K2: Dry t if all chipped
A3: R6 (FY2024) | B3: 314 | C3: 菅野 | D3: (1068-8.-63.-76.-87.-97)/チ | E3: 39 | F3: 13.4 | G3: 52 | H3: 1171 | I3: Cut & leave (伐捨) | J3: 施業放置林整備事業 | K3: =H3*Assumptions!$B$2
A4: R8 (FY2026) | B4: 491 | C4: 神末 | D4: 1810-31 | E4: 22 | F4: 17.17 | G4: 59 | H4: 1099 | I4: Extracted (搬出) | J4: 美しい森林づくり基盤整備事業 | K4: =H4*Assumptions!$B$2
A5: R6 (FY2024) | B5: 315 | C5: 菅野 | D5: 1068-63.-76 | E5: 39 | F5: 9.08 | G5: 52 | H5: 794 | I5: Cut & leave (伐捨) | J5: 施業放置林整備事業 | K5: =H5*Assumptions!$B$2
A6: R8 (FY2026) | B6: 466 | C6: 菅野 | D6: 1223-20 | E6: 36 | F6: 6.35 | G6: 76 | H6: 730 | I6: Cut & leave (伐捨) | J6: 施業放置林整備事業 | K6: =H6*Assumptions!$B$2
A7: R6 (FY2024) | B7: 313 | C7: 菅野 | D7: (1068-8.-63.-76.-87.-97)/チ | E7: 39 | F7: 7.81 | G7: 52 | H7: 683 | I7: Cut & leave (伐捨) | J7: 施業放置林整備事業 | K7: =H7*Assumptions!$B$2
A8: R6 (FY2024) | B8: 351 | C8: 神末 | D8: 1810-1 | E8: 22 | F8: 9.92 | G8: 67 | H8: 671 | I8: Cut & leave (伐捨) | J8: 美しい森林づくり基盤整備事業 | K8: =H8*Assumptions!$B$2
A9: R7 (FY2025) | B9: 412 | C9: 神末 | D9: 3059-334.-335 | F9: 5.27 | G9: 87 | H9: 606 | I9: Cut & leave (伐捨) | J9: 施業放置林整備事業 | K9: =H9*Assumptions!$B$2
A10: R7 (FY2025) | B10: 404 | C10: 神末 | D10: 2267.2258-1.-2 2264.2265.2179-162.-163. | E10: 14 | F10: 4.98 | G10: 76 | H10: 573 | I10: Cut & leave (伐捨) | J10: 施業放置林整備事業 | K10: =H10*Assumptions!$B$2
A11: R7 (FY2025) | B11: 401 | C11: 神末 | D11: 3059-336 | E11: 10 | F11: 7.78 | G11: 31 | H11: 548 | I11: Cut & leave (伐捨) | J11: 施業放置林整備事業 | K11: =H11*Assumptions!$B$2
A12: R7 (FY2025) | B12: 405 | C12: 神末 | D12: 2179-104.-252 | E12: 16 | F12: 4.95 | G12: 58 | H12: 539 | I12: Cut & leave (伐捨) | J12: 施業放置林整備事業 | K12: =H12*Assumptions!$B$2
A13: R7 (FY2025) | B13: 407 | C13: 菅野 | D13: 2960-105.-106 | E13: 35 | F13: 3.97 | G13: 63 | H13: 457 | I13: Cut & leave (伐捨) | J13: 施業放置林整備事業 | K13: =H13*Assumptions!$B$2
A14: R8 (FY2026) | B14: 462 | C14: 土屋原 | D14: 533 | E14: 69 | F14: 3.79 | G14: 61 | H14: 436 | I14: Cut & leave (伐捨) | J14: 施業放置林整備事業 | K14: =H14*Assumptions!$B$2
A15: R6 (FY2024) | B15: 320 | C15: 土屋原 | D15: 2792-48.-49 | E15: 52 | F15: 3.86 | G15: 59 | H15: 420 | I15: Cut & leave (伐捨) | J15: 施業放置林整備事業 | K15: =H15*Assumptions!$B$2
A16: R8 (FY2026) | B16: 459 | C16: 菅野 | D16: 964-47.-77 | E16: 48 | F16: 3.54 | G16: 59 | H16: 386 | I16: Cut & leave (伐捨) | J16: 施業放置林整備事業 | K16: =H16*Assumptions!$B$2
A17: R8 (FY2026) | B17: 501 | C17: 土屋原 | D17: 2523~2528,2540~2545 | E17: 51 | F17: 5.43 | G17: 64 | H17: 368 | I17: Extracted (搬出) | J17: 美しい森林づくり基盤整備事業 | K17: =H17*Assumptions!$B$2
A18: R6 (FY2024) | B18: 302 | C18: 神末 | D18: 2179-86.-87 | E18: 15 | F18: 3.82 | G18: 55 | H18: 334 | I18: Cut & leave (伐捨) | J18: 施業放置林整備事業 | K18: =H18*Assumptions!$B$2
A19: R7 (FY2025) | B19: 409 | C19: 菅野 | D19: 1032-29 | E19: 44 | F19: 2.68 | G19: 59 | H19: 292 | I19: Cut & leave (伐捨) | J19: 施業放置林整備事業 | K19: =H19*Assumptions!$B$2
A20: R6 (FY2024) | B20: 359 | C20: 土屋原 | D20: 3278-1/ウチ | E20: 56 | F20: 4.2 | G20: 80 | H20: 284 | I20: Extracted (搬出) | J20: 美しい森林づくり基盤整備事業 | K20: =H20*Assumptions!$B$2
A21: R7 (FY2025) | B21: 435 | C21: 菅野 | D21: 1970 | E21: 0c 95 | F21: 2.61 | G21: 59 | H21: 284 | I21: Cut & leave (伐捨) | J21: 施業放置林整備事業 | K21: =H21*Assumptions!$B$2
... A65: R6 (FY2024) | B65: 319 | C65: 土屋原 | D65: 2792-52 | E65: 52 | F65: 0.92 | G65: 59 | H65: 101 | I65: Cut & leave (伐捨) | J65: 施業放置林整備事業 | K65: =H65*Assumptions!$B$2
